[2023-09-26T11:55:05.648+0000] {taskinstance.py:1103} INFO - Dependencies all met for dep_context=non-requeueable deps ti=<TaskInstance: load_data.load_to_fact_table scheduled__2023-09-26T02:10:00+00:00 [queued]>
[2023-09-26T11:55:05.654+0000] {taskinstance.py:1103} INFO - Dependencies all met for dep_context=requeueable deps ti=<TaskInstance: load_data.load_to_fact_table scheduled__2023-09-26T02:10:00+00:00 [queued]>
[2023-09-26T11:55:05.655+0000] {taskinstance.py:1308} INFO - Starting attempt 1 of 1
[2023-09-26T11:55:05.666+0000] {taskinstance.py:1327} INFO - Executing <Task(_PythonDecoratedOperator): load_to_fact_table> on 2023-09-26 02:10:00+00:00
[2023-09-26T11:55:05.671+0000] {standard_task_runner.py:57} INFO - Started process 2575 to run task
[2023-09-26T11:55:05.675+0000] {standard_task_runner.py:84} INFO - Running: ['***', 'tasks', 'run', 'load_data', 'load_to_fact_table', 'scheduled__2023-09-26T02:10:00+00:00', '--job-id', '5790', '--raw', '--subdir', 'DAGS_FOLDER/load_data.py', '--cfg-path', '/tmp/tmpto1yy4p4']
[2023-09-26T11:55:05.679+0000] {standard_task_runner.py:85} INFO - Job 5790: Subtask load_to_fact_table
[2023-09-26T11:55:05.735+0000] {task_command.py:410} INFO - Running <TaskInstance: load_data.load_to_fact_table scheduled__2023-09-26T02:10:00+00:00 [running]> on host 833e75d2e24d
[2023-09-26T11:55:05.804+0000] {taskinstance.py:1547} INFO - Exporting env vars: AIRFLOW_CTX_DAG_OWNER='***' AIRFLOW_CTX_DAG_ID='load_data' AIRFLOW_CTX_TASK_ID='load_to_fact_table' AIRFLOW_CTX_EXECUTION_DATE='2023-09-26T02:10:00+00:00' AIRFLOW_CTX_TRY_NUMBER='1' AIRFLOW_CTX_DAG_RUN_ID='scheduled__2023-09-26T02:10:00+00:00'
[2023-09-26T11:55:05.883+0000] {connectionpool.py:813} WARNING - Retrying (Retry(total=2, connect=None, read=None, redirect=None, status=None)) after connection broken by 'NewConnectionError('<urllib3.connection.HTTPSConnection object at 0x7fa17f31fdd0>: Failed to establish a new connection: [Errno -2] Name or service not known')': /token
[2023-09-26T11:55:05.885+0000] {connectionpool.py:813} WARNING - Retrying (Retry(total=1, connect=None, read=None, redirect=None, status=None)) after connection broken by 'NewConnectionError('<urllib3.connection.HTTPSConnection object at 0x7fa17f2d9850>: Failed to establish a new connection: [Errno -2] Name or service not known')': /token
[2023-09-26T11:55:05.887+0000] {connectionpool.py:813} WARNING - Retrying (Retry(total=0, connect=None, read=None, redirect=None, status=None)) after connection broken by 'NewConnectionError('<urllib3.connection.HTTPSConnection object at 0x7fa17f2d9c10>: Failed to establish a new connection: [Errno -2] Name or service not known')': /token
[2023-09-26T11:55:06.381+0000] {connectionpool.py:813} WARNING - Retrying (Retry(total=2, connect=None, read=None, redirect=None, status=None)) after connection broken by 'NewConnectionError('<urllib3.connection.HTTPSConnection object at 0x7fa17f2f15d0>: Failed to establish a new connection: [Errno -2] Name or service not known')': /token
[2023-09-26T11:55:06.383+0000] {connectionpool.py:813} WARNING - Retrying (Retry(total=1, connect=None, read=None, redirect=None, status=None)) after connection broken by 'NewConnectionError('<urllib3.connection.HTTPSConnection object at 0x7fa17f2f1bd0>: Failed to establish a new connection: [Errno -2] Name or service not known')': /token
[2023-09-26T11:55:06.385+0000] {connectionpool.py:813} WARNING - Retrying (Retry(total=0, connect=None, read=None, redirect=None, status=None)) after connection broken by 'NewConnectionError('<urllib3.connection.HTTPSConnection object at 0x7fa17f2f1f90>: Failed to establish a new connection: [Errno -2] Name or service not known')': /token
[2023-09-26T11:55:07.929+0000] {connectionpool.py:813} WARNING - Retrying (Retry(total=2, connect=None, read=None, redirect=None, status=None)) after connection broken by 'NewConnectionError('<urllib3.connection.HTTPSConnection object at 0x7fa17f2fb950>: Failed to establish a new connection: [Errno -2] Name or service not known')': /token
[2023-09-26T11:55:07.932+0000] {connectionpool.py:813} WARNING - Retrying (Retry(total=1, connect=None, read=None, redirect=None, status=None)) after connection broken by 'NewConnectionError('<urllib3.connection.HTTPSConnection object at 0x7fa17f2fbfd0>: Failed to establish a new connection: [Errno -2] Name or service not known')': /token
[2023-09-26T11:55:07.934+0000] {connectionpool.py:813} WARNING - Retrying (Retry(total=0, connect=None, read=None, redirect=None, status=None)) after connection broken by 'NewConnectionError('<urllib3.connection.HTTPSConnection object at 0x7fa17f305410>: Failed to establish a new connection: [Errno -2] Name or service not known')': /token
[2023-09-26T11:55:11.194+0000] {connectionpool.py:813} WARNING - Retrying (Retry(total=2, connect=None, read=None, redirect=None, status=None)) after connection broken by 'NewConnectionError('<urllib3.connection.HTTPSConnection object at 0x7fa17f2d9490>: Failed to establish a new connection: [Errno -2] Name or service not known')': /token
[2023-09-26T11:55:11.196+0000] {connectionpool.py:813} WARNING - Retrying (Retry(total=1, connect=None, read=None, redirect=None, status=None)) after connection broken by 'NewConnectionError('<urllib3.connection.HTTPSConnection object at 0x7fa17f2d9d90>: Failed to establish a new connection: [Errno -2] Name or service not known')': /token
[2023-09-26T11:55:11.198+0000] {connectionpool.py:813} WARNING - Retrying (Retry(total=0, connect=None, read=None, redirect=None, status=None)) after connection broken by 'NewConnectionError('<urllib3.connection.HTTPSConnection object at 0x7fa17f2d9890>: Failed to establish a new connection: [Errno -2] Name or service not known')': /token
[2023-09-26T11:55:13.569+0000] {connectionpool.py:813} WARNING - Retrying (Retry(total=2, connect=None, read=None, redirect=None, status=None)) after connection broken by 'NewConnectionError('<urllib3.connection.HTTPSConnection object at 0x7fa17f305f50>: Failed to establish a new connection: [Errno -2] Name or service not known')': /token
[2023-09-26T11:55:13.571+0000] {connectionpool.py:813} WARNING - Retrying (Retry(total=1, connect=None, read=None, redirect=None, status=None)) after connection broken by 'NewConnectionError('<urllib3.connection.HTTPSConnection object at 0x7fa17f28e610>: Failed to establish a new connection: [Errno -2] Name or service not known')': /token
[2023-09-26T11:55:13.573+0000] {connectionpool.py:813} WARNING - Retrying (Retry(total=0, connect=None, read=None, redirect=None, status=None)) after connection broken by 'NewConnectionError('<urllib3.connection.HTTPSConnection object at 0x7fa17f28e990>: Failed to establish a new connection: [Errno -2] Name or service not known')': /token
[2023-09-26T11:55:29.690+0000] {logging_mixin.py:149} INFO - Connection Succesful
[2023-09-26T11:55:31.539+0000] {logging_mixin.py:149} INFO - Loaded 0 rows to BigQuery
[2023-09-26T11:55:31.542+0000] {python.py:183} INFO - Done. Returned value was: None
[2023-09-26T11:55:31.550+0000] {taskinstance.py:1350} INFO - Marking task as SUCCESS. dag_id=load_data, task_id=load_to_fact_table, execution_date=20230926T021000, start_date=20230926T115505, end_date=20230926T115531
[2023-09-26T11:55:31.568+0000] {local_task_job_runner.py:225} INFO - Task exited with return code 0
[2023-09-26T11:55:31.580+0000] {taskinstance.py:2651} INFO - 0 downstream tasks scheduled from follow-on schedule check
