[2023-09-25T09:59:55.955+0000] {taskinstance.py:1103} INFO - Dependencies all met for dep_context=non-requeueable deps ti=<TaskInstance: load_data.load_to_fact_table scheduled__2023-09-25T09:50:00+00:00 [queued]>
[2023-09-25T09:59:55.961+0000] {taskinstance.py:1103} INFO - Dependencies all met for dep_context=requeueable deps ti=<TaskInstance: load_data.load_to_fact_table scheduled__2023-09-25T09:50:00+00:00 [queued]>
[2023-09-25T09:59:55.961+0000] {taskinstance.py:1308} INFO - Starting attempt 1 of 1
[2023-09-25T09:59:55.973+0000] {taskinstance.py:1327} INFO - Executing <Task(_PythonDecoratedOperator): load_to_fact_table> on 2023-09-25 09:50:00+00:00
[2023-09-25T09:59:55.978+0000] {standard_task_runner.py:57} INFO - Started process 19774 to run task
[2023-09-25T09:59:55.982+0000] {standard_task_runner.py:84} INFO - Running: ['***', 'tasks', 'run', 'load_data', 'load_to_fact_table', 'scheduled__2023-09-25T09:50:00+00:00', '--job-id', '5631', '--raw', '--subdir', 'DAGS_FOLDER/load_data.py', '--cfg-path', '/tmp/tmp76fhzu98']
[2023-09-25T09:59:55.984+0000] {standard_task_runner.py:85} INFO - Job 5631: Subtask load_to_fact_table
[2023-09-25T09:59:56.026+0000] {task_command.py:410} INFO - Running <TaskInstance: load_data.load_to_fact_table scheduled__2023-09-25T09:50:00+00:00 [running]> on host 833e75d2e24d
[2023-09-25T09:59:56.089+0000] {taskinstance.py:1547} INFO - Exporting env vars: AIRFLOW_CTX_DAG_OWNER='***' AIRFLOW_CTX_DAG_ID='load_data' AIRFLOW_CTX_TASK_ID='load_to_fact_table' AIRFLOW_CTX_EXECUTION_DATE='2023-09-25T09:50:00+00:00' AIRFLOW_CTX_TRY_NUMBER='1' AIRFLOW_CTX_DAG_RUN_ID='scheduled__2023-09-25T09:50:00+00:00'
[2023-09-25T09:59:56.163+0000] {connectionpool.py:813} WARNING - Retrying (Retry(total=2, connect=None, read=None, redirect=None, status=None)) after connection broken by 'NewConnectionError('<urllib3.connection.HTTPSConnection object at 0x7fa17f2d2bd0>: Failed to establish a new connection: [Errno -2] Name or service not known')': /token
[2023-09-25T09:59:56.165+0000] {connectionpool.py:813} WARNING - Retrying (Retry(total=1, connect=None, read=None, redirect=None, status=None)) after connection broken by 'NewConnectionError('<urllib3.connection.HTTPSConnection object at 0x7fa17f2d2f50>: Failed to establish a new connection: [Errno -2] Name or service not known')': /token
[2023-09-25T09:59:56.167+0000] {connectionpool.py:813} WARNING - Retrying (Retry(total=0, connect=None, read=None, redirect=None, status=None)) after connection broken by 'NewConnectionError('<urllib3.connection.HTTPSConnection object at 0x7fa17f2f4350>: Failed to establish a new connection: [Errno -2] Name or service not known')': /token
[2023-09-25T09:59:56.299+0000] {connectionpool.py:813} WARNING - Retrying (Retry(total=2, connect=None, read=None, redirect=None, status=None)) after connection broken by 'NewConnectionError('<urllib3.connection.HTTPSConnection object at 0x7fa17f2f4cd0>: Failed to establish a new connection: [Errno -2] Name or service not known')': /token
[2023-09-25T09:59:56.301+0000] {connectionpool.py:813} WARNING - Retrying (Retry(total=1, connect=None, read=None, redirect=None, status=None)) after connection broken by 'NewConnectionError('<urllib3.connection.HTTPSConnection object at 0x7fa17f2fb310>: Failed to establish a new connection: [Errno -2] Name or service not known')': /token
[2023-09-25T09:59:56.303+0000] {connectionpool.py:813} WARNING - Retrying (Retry(total=0, connect=None, read=None, redirect=None, status=None)) after connection broken by 'NewConnectionError('<urllib3.connection.HTTPSConnection object at 0x7fa17f2fb6d0>: Failed to establish a new connection: [Errno -2] Name or service not known')': /token
[2023-09-25T09:59:57.544+0000] {connectionpool.py:813} WARNING - Retrying (Retry(total=2, connect=None, read=None, redirect=None, status=None)) after connection broken by 'NewConnectionError('<urllib3.connection.HTTPSConnection object at 0x7fa17f305090>: Failed to establish a new connection: [Errno -2] Name or service not known')': /token
[2023-09-25T09:59:57.546+0000] {connectionpool.py:813} WARNING - Retrying (Retry(total=1, connect=None, read=None, redirect=None, status=None)) after connection broken by 'NewConnectionError('<urllib3.connection.HTTPSConnection object at 0x7fa17f305790>: Failed to establish a new connection: [Errno -2] Name or service not known')': /token
[2023-09-25T09:59:57.549+0000] {connectionpool.py:813} WARNING - Retrying (Retry(total=0, connect=None, read=None, redirect=None, status=None)) after connection broken by 'NewConnectionError('<urllib3.connection.HTTPSConnection object at 0x7fa17f305b10>: Failed to establish a new connection: [Errno -2] Name or service not known')': /token
[2023-09-25T10:00:00.618+0000] {connectionpool.py:813} WARNING - Retrying (Retry(total=2, connect=None, read=None, redirect=None, status=None)) after connection broken by 'NewConnectionError('<urllib3.connection.HTTPSConnection object at 0x7fa17f2f40d0>: Failed to establish a new connection: [Errno -2] Name or service not known')': /token
[2023-09-25T10:00:00.620+0000] {connectionpool.py:813} WARNING - Retrying (Retry(total=1, connect=None, read=None, redirect=None, status=None)) after connection broken by 'NewConnectionError('<urllib3.connection.HTTPSConnection object at 0x7fa17f2d2f50>: Failed to establish a new connection: [Errno -2] Name or service not known')': /token
[2023-09-25T10:00:00.622+0000] {connectionpool.py:813} WARNING - Retrying (Retry(total=0, connect=None, read=None, redirect=None, status=None)) after connection broken by 'NewConnectionError('<urllib3.connection.HTTPSConnection object at 0x7fa17f2d2950>: Failed to establish a new connection: [Errno -2] Name or service not known')': /token
[2023-09-25T10:00:03.324+0000] {connectionpool.py:813} WARNING - Retrying (Retry(total=2, connect=None, read=None, redirect=None, status=None)) after connection broken by 'NewConnectionError('<urllib3.connection.HTTPSConnection object at 0x7fa17f28b510>: Failed to establish a new connection: [Errno -2] Name or service not known')': /token
[2023-09-25T10:00:03.326+0000] {connectionpool.py:813} WARNING - Retrying (Retry(total=1, connect=None, read=None, redirect=None, status=None)) after connection broken by 'NewConnectionError('<urllib3.connection.HTTPSConnection object at 0x7fa17f28bc90>: Failed to establish a new connection: [Errno -2] Name or service not known')': /token
[2023-09-25T10:00:03.328+0000] {connectionpool.py:813} WARNING - Retrying (Retry(total=0, connect=None, read=None, redirect=None, status=None)) after connection broken by 'NewConnectionError('<urllib3.connection.HTTPSConnection object at 0x7fa17f296050>: Failed to establish a new connection: [Errno -2] Name or service not known')': /token
[2023-09-25T10:00:17.385+0000] {logging_mixin.py:149} INFO - Connection Succesful
[2023-09-25T10:00:19.698+0000] {logging_mixin.py:149} INFO - Loaded 1 rows to BigQuery
[2023-09-25T10:00:19.701+0000] {python.py:183} INFO - Done. Returned value was: None
[2023-09-25T10:00:19.710+0000] {taskinstance.py:1350} INFO - Marking task as SUCCESS. dag_id=load_data, task_id=load_to_fact_table, execution_date=20230925T095000, start_date=20230925T095955, end_date=20230925T100019
[2023-09-25T10:00:19.732+0000] {local_task_job_runner.py:225} INFO - Task exited with return code 0
[2023-09-25T10:00:19.743+0000] {taskinstance.py:2651} INFO - 0 downstream tasks scheduled from follow-on schedule check
