[2023-09-23T16:35:00.755+0000] {taskinstance.py:1103} INFO - Dependencies all met for dep_context=non-requeueable deps ti=<TaskInstance: load_data.load_to_fact_table scheduled__2023-09-23T16:30:00+00:00 [queued]>
[2023-09-23T16:35:00.761+0000] {taskinstance.py:1103} INFO - Dependencies all met for dep_context=requeueable deps ti=<TaskInstance: load_data.load_to_fact_table scheduled__2023-09-23T16:30:00+00:00 [queued]>
[2023-09-23T16:35:00.761+0000] {taskinstance.py:1308} INFO - Starting attempt 1 of 1
[2023-09-23T16:35:00.770+0000] {taskinstance.py:1327} INFO - Executing <Task(_PythonDecoratedOperator): load_to_fact_table> on 2023-09-23 16:30:00+00:00
[2023-09-23T16:35:00.775+0000] {standard_task_runner.py:57} INFO - Started process 2994 to run task
[2023-09-23T16:35:00.777+0000] {standard_task_runner.py:84} INFO - Running: ['***', 'tasks', 'run', 'load_data', 'load_to_fact_table', 'scheduled__2023-09-23T16:30:00+00:00', '--job-id', '5442', '--raw', '--subdir', 'DAGS_FOLDER/load_data.py', '--cfg-path', '/tmp/tmpcmmm2sdi']
[2023-09-23T16:35:00.781+0000] {standard_task_runner.py:85} INFO - Job 5442: Subtask load_to_fact_table
[2023-09-23T16:35:00.814+0000] {task_command.py:410} INFO - Running <TaskInstance: load_data.load_to_fact_table scheduled__2023-09-23T16:30:00+00:00 [running]> on host 833e75d2e24d
[2023-09-23T16:35:00.881+0000] {taskinstance.py:1547} INFO - Exporting env vars: AIRFLOW_CTX_DAG_OWNER='***' AIRFLOW_CTX_DAG_ID='load_data' AIRFLOW_CTX_TASK_ID='load_to_fact_table' AIRFLOW_CTX_EXECUTION_DATE='2023-09-23T16:30:00+00:00' AIRFLOW_CTX_TRY_NUMBER='1' AIRFLOW_CTX_DAG_RUN_ID='scheduled__2023-09-23T16:30:00+00:00'
[2023-09-23T16:35:02.484+0000] {logging_mixin.py:149} INFO - Connection Succesful
[2023-09-23T16:35:04.400+0000] {logging_mixin.py:149} INFO - Loaded 4 rows to BigQuery
[2023-09-23T16:35:04.401+0000] {taskinstance.py:1824} ERROR - Task failed with exception
Traceback (most recent call last):
  File "/home/airflow/.local/lib/python3.7/site-packages/airflow/decorators/base.py", line 220, in execute
    return_value = super().execute(context)
  File "/home/airflow/.local/lib/python3.7/site-packages/airflow/operators/python.py", line 181, in execute
    return_value = self.execute_callable()
  File "/home/airflow/.local/lib/python3.7/site-packages/airflow/operators/python.py", line 198, in execute_callable
    return self.python_callable(*self.op_args, **self.op_kwargs)
  File "/opt/airflow/dags/load_data.py", line 21, in load_to_fact_table
    _load_to_fact_table()
  File "/opt/airflow/helper/helper.py", line 105, in _load_to_fact_table
    results_df.to_csv(f"/opt/airflow/data/data_{datetime.datetime.now().strftime('%Y-%m-%d')}.csv", mode ='r')
  File "/home/airflow/.local/lib/python3.7/site-packages/pandas/core/generic.py", line 3482, in to_csv
    storage_options=storage_options,
  File "/home/airflow/.local/lib/python3.7/site-packages/pandas/io/formats/format.py", line 1105, in to_csv
    csv_formatter.save()
  File "/home/airflow/.local/lib/python3.7/site-packages/pandas/io/formats/csvs.py", line 243, in save
    storage_options=self.storage_options,
  File "/home/airflow/.local/lib/python3.7/site-packages/pandas/io/common.py", line 707, in get_handle
    newline="",
FileNotFoundError: [Errno 2] No such file or directory: '/opt/airflow/data/data_2023-09-23.csv'
[2023-09-23T16:35:04.414+0000] {taskinstance.py:1350} INFO - Marking task as FAILED. dag_id=load_data, task_id=load_to_fact_table, execution_date=20230923T163000, start_date=20230923T163500, end_date=20230923T163504
[2023-09-23T16:35:04.424+0000] {standard_task_runner.py:109} ERROR - Failed to execute job 5442 for task load_to_fact_table ([Errno 2] No such file or directory: '/opt/airflow/data/data_2023-09-23.csv'; 2994)
[2023-09-23T16:35:04.440+0000] {local_task_job_runner.py:225} INFO - Task exited with return code 1
[2023-09-23T16:35:04.459+0000] {taskinstance.py:2651} INFO - 0 downstream tasks scheduled from follow-on schedule check
