[2023-09-26T11:55:06.479+0000] {taskinstance.py:1103} INFO - Dependencies all met for dep_context=non-requeueable deps ti=<TaskInstance: load_data.load_to_fact_table scheduled__2023-09-26T11:50:00+00:00 [queued]>
[2023-09-26T11:55:06.486+0000] {taskinstance.py:1103} INFO - Dependencies all met for dep_context=requeueable deps ti=<TaskInstance: load_data.load_to_fact_table scheduled__2023-09-26T11:50:00+00:00 [queued]>
[2023-09-26T11:55:06.487+0000] {taskinstance.py:1308} INFO - Starting attempt 1 of 1
[2023-09-26T11:55:06.497+0000] {taskinstance.py:1327} INFO - Executing <Task(_PythonDecoratedOperator): load_to_fact_table> on 2023-09-26 11:50:00+00:00
[2023-09-26T11:55:06.502+0000] {standard_task_runner.py:57} INFO - Started process 2576 to run task
[2023-09-26T11:55:06.505+0000] {standard_task_runner.py:84} INFO - Running: ['***', 'tasks', 'run', 'load_data', 'load_to_fact_table', 'scheduled__2023-09-26T11:50:00+00:00', '--job-id', '5791', '--raw', '--subdir', 'DAGS_FOLDER/load_data.py', '--cfg-path', '/tmp/tmp6wfhafo_']
[2023-09-26T11:55:06.507+0000] {standard_task_runner.py:85} INFO - Job 5791: Subtask load_to_fact_table
[2023-09-26T11:55:06.541+0000] {task_command.py:410} INFO - Running <TaskInstance: load_data.load_to_fact_table scheduled__2023-09-26T11:50:00+00:00 [running]> on host 833e75d2e24d
[2023-09-26T11:55:06.603+0000] {taskinstance.py:1547} INFO - Exporting env vars: AIRFLOW_CTX_DAG_OWNER='***' AIRFLOW_CTX_DAG_ID='load_data' AIRFLOW_CTX_TASK_ID='load_to_fact_table' AIRFLOW_CTX_EXECUTION_DATE='2023-09-26T11:50:00+00:00' AIRFLOW_CTX_TRY_NUMBER='1' AIRFLOW_CTX_DAG_RUN_ID='scheduled__2023-09-26T11:50:00+00:00'
[2023-09-26T11:55:06.677+0000] {connectionpool.py:813} WARNING - Retrying (Retry(total=2, connect=None, read=None, redirect=None, status=None)) after connection broken by 'NewConnectionError('<urllib3.connection.HTTPSConnection object at 0x7fa17f2d9650>: Failed to establish a new connection: [Errno -2] Name or service not known')': /token
[2023-09-26T11:55:06.679+0000] {connectionpool.py:813} WARNING - Retrying (Retry(total=1, connect=None, read=None, redirect=None, status=None)) after connection broken by 'NewConnectionError('<urllib3.connection.HTTPSConnection object at 0x7fa17f2d99d0>: Failed to establish a new connection: [Errno -2] Name or service not known')': /token
[2023-09-26T11:55:06.681+0000] {connectionpool.py:813} WARNING - Retrying (Retry(total=0, connect=None, read=None, redirect=None, status=None)) after connection broken by 'NewConnectionError('<urllib3.connection.HTTPSConnection object at 0x7fa17f2d9d90>: Failed to establish a new connection: [Errno -2] Name or service not known')': /token
[2023-09-26T11:55:06.848+0000] {connectionpool.py:813} WARNING - Retrying (Retry(total=2, connect=None, read=None, redirect=None, status=None)) after connection broken by 'NewConnectionError('<urllib3.connection.HTTPSConnection object at 0x7fa17f2f4750>: Failed to establish a new connection: [Errno -2] Name or service not known')': /token
[2023-09-26T11:55:06.851+0000] {connectionpool.py:813} WARNING - Retrying (Retry(total=1, connect=None, read=None, redirect=None, status=None)) after connection broken by 'NewConnectionError('<urllib3.connection.HTTPSConnection object at 0x7fa17f2f4d50>: Failed to establish a new connection: [Errno -2] Name or service not known')': /token
[2023-09-26T11:55:06.853+0000] {connectionpool.py:813} WARNING - Retrying (Retry(total=0, connect=None, read=None, redirect=None, status=None)) after connection broken by 'NewConnectionError('<urllib3.connection.HTTPSConnection object at 0x7fa17f2fe150>: Failed to establish a new connection: [Errno -2] Name or service not known')': /token
[2023-09-26T11:55:08.495+0000] {connectionpool.py:813} WARNING - Retrying (Retry(total=2, connect=None, read=None, redirect=None, status=None)) after connection broken by 'NewConnectionError('<urllib3.connection.HTTPSConnection object at 0x7fa17f2fead0>: Failed to establish a new connection: [Errno -2] Name or service not known')': /token
[2023-09-26T11:55:08.497+0000] {connectionpool.py:813} WARNING - Retrying (Retry(total=1, connect=None, read=None, redirect=None, status=None)) after connection broken by 'NewConnectionError('<urllib3.connection.HTTPSConnection object at 0x7fa17f306210>: Failed to establish a new connection: [Errno -2] Name or service not known')': /token
[2023-09-26T11:55:08.500+0000] {connectionpool.py:813} WARNING - Retrying (Retry(total=0, connect=None, read=None, redirect=None, status=None)) after connection broken by 'NewConnectionError('<urllib3.connection.HTTPSConnection object at 0x7fa17f306590>: Failed to establish a new connection: [Errno -2] Name or service not known')': /token
[2023-09-26T11:55:10.531+0000] {connectionpool.py:813} WARNING - Retrying (Retry(total=2, connect=None, read=None, redirect=None, status=None)) after connection broken by 'NewConnectionError('<urllib3.connection.HTTPSConnection object at 0x7fa17f2d98d0>: Failed to establish a new connection: [Errno -2] Name or service not known')': /token
[2023-09-26T11:55:10.533+0000] {connectionpool.py:813} WARNING - Retrying (Retry(total=1, connect=None, read=None, redirect=None, status=None)) after connection broken by 'NewConnectionError('<urllib3.connection.HTTPSConnection object at 0x7fa17f2d96d0>: Failed to establish a new connection: [Errno -2] Name or service not known')': /token
[2023-09-26T11:55:10.535+0000] {connectionpool.py:813} WARNING - Retrying (Retry(total=0, connect=None, read=None, redirect=None, status=None)) after connection broken by 'NewConnectionError('<urllib3.connection.HTTPSConnection object at 0x7fa17f2c8f50>: Failed to establish a new connection: [Errno -2] Name or service not known')': /token
[2023-09-26T11:55:14.493+0000] {connectionpool.py:813} WARNING - Retrying (Retry(total=2, connect=None, read=None, redirect=None, status=None)) after connection broken by 'NewConnectionError('<urllib3.connection.HTTPSConnection object at 0x7fa17f28f2d0>: Failed to establish a new connection: [Errno -2] Name or service not known')': /token
[2023-09-26T11:55:14.496+0000] {connectionpool.py:813} WARNING - Retrying (Retry(total=1, connect=None, read=None, redirect=None, status=None)) after connection broken by 'NewConnectionError('<urllib3.connection.HTTPSConnection object at 0x7fa17f28f710>: Failed to establish a new connection: [Errno -2] Name or service not known')': /token
[2023-09-26T11:55:14.497+0000] {connectionpool.py:813} WARNING - Retrying (Retry(total=0, connect=None, read=None, redirect=None, status=None)) after connection broken by 'NewConnectionError('<urllib3.connection.HTTPSConnection object at 0x7fa17f28fa90>: Failed to establish a new connection: [Errno -2] Name or service not known')': /token
[2023-09-26T11:55:19.750+0000] {logging_mixin.py:149} INFO - Connection Succesful
[2023-09-26T11:55:21.658+0000] {logging_mixin.py:149} INFO - Loaded 0 rows to BigQuery
[2023-09-26T11:55:21.661+0000] {python.py:183} INFO - Done. Returned value was: None
[2023-09-26T11:55:21.670+0000] {taskinstance.py:1350} INFO - Marking task as SUCCESS. dag_id=load_data, task_id=load_to_fact_table, execution_date=20230926T115000, start_date=20230926T115506, end_date=20230926T115521
[2023-09-26T11:55:21.718+0000] {local_task_job_runner.py:225} INFO - Task exited with return code 0
[2023-09-26T11:55:21.730+0000] {taskinstance.py:2651} INFO - 0 downstream tasks scheduled from follow-on schedule check
