[2023-09-25T10:00:01.908+0000] {taskinstance.py:1103} INFO - Dependencies all met for dep_context=non-requeueable deps ti=<TaskInstance: load_data.load_to_fact_table scheduled__2023-09-25T09:55:00+00:00 [queued]>
[2023-09-25T10:00:01.914+0000] {taskinstance.py:1103} INFO - Dependencies all met for dep_context=requeueable deps ti=<TaskInstance: load_data.load_to_fact_table scheduled__2023-09-25T09:55:00+00:00 [queued]>
[2023-09-25T10:00:01.914+0000] {taskinstance.py:1308} INFO - Starting attempt 1 of 1
[2023-09-25T10:00:01.923+0000] {taskinstance.py:1327} INFO - Executing <Task(_PythonDecoratedOperator): load_to_fact_table> on 2023-09-25 09:55:00+00:00
[2023-09-25T10:00:01.928+0000] {standard_task_runner.py:57} INFO - Started process 19777 to run task
[2023-09-25T10:00:01.931+0000] {standard_task_runner.py:84} INFO - Running: ['***', 'tasks', 'run', 'load_data', 'load_to_fact_table', 'scheduled__2023-09-25T09:55:00+00:00', '--job-id', '5632', '--raw', '--subdir', 'DAGS_FOLDER/load_data.py', '--cfg-path', '/tmp/tmp79zb_hov']
[2023-09-25T10:00:01.932+0000] {standard_task_runner.py:85} INFO - Job 5632: Subtask load_to_fact_table
[2023-09-25T10:00:01.965+0000] {task_command.py:410} INFO - Running <TaskInstance: load_data.load_to_fact_table scheduled__2023-09-25T09:55:00+00:00 [running]> on host 833e75d2e24d
[2023-09-25T10:00:02.038+0000] {taskinstance.py:1547} INFO - Exporting env vars: AIRFLOW_CTX_DAG_OWNER='***' AIRFLOW_CTX_DAG_ID='load_data' AIRFLOW_CTX_TASK_ID='load_to_fact_table' AIRFLOW_CTX_EXECUTION_DATE='2023-09-25T09:55:00+00:00' AIRFLOW_CTX_TRY_NUMBER='1' AIRFLOW_CTX_DAG_RUN_ID='scheduled__2023-09-25T09:55:00+00:00'
[2023-09-25T10:00:02.123+0000] {connectionpool.py:813} WARNING - Retrying (Retry(total=2, connect=None, read=None, redirect=None, status=None)) after connection broken by 'NewConnectionError('<urllib3.connection.HTTPSConnection object at 0x7fa17f2d9110>: Failed to establish a new connection: [Errno -2] Name or service not known')': /token
[2023-09-25T10:00:02.125+0000] {connectionpool.py:813} WARNING - Retrying (Retry(total=1, connect=None, read=None, redirect=None, status=None)) after connection broken by 'NewConnectionError('<urllib3.connection.HTTPSConnection object at 0x7fa17f2d9490>: Failed to establish a new connection: [Errno -2] Name or service not known')': /token
[2023-09-25T10:00:02.127+0000] {connectionpool.py:813} WARNING - Retrying (Retry(total=0, connect=None, read=None, redirect=None, status=None)) after connection broken by 'NewConnectionError('<urllib3.connection.HTTPSConnection object at 0x7fa17f2d9850>: Failed to establish a new connection: [Errno -2] Name or service not known')': /token
[2023-09-25T10:00:03.015+0000] {connectionpool.py:813} WARNING - Retrying (Retry(total=2, connect=None, read=None, redirect=None, status=None)) after connection broken by 'NewConnectionError('<urllib3.connection.HTTPSConnection object at 0x7fa17f2eb210>: Failed to establish a new connection: [Errno -2] Name or service not known')': /token
[2023-09-25T10:00:03.017+0000] {connectionpool.py:813} WARNING - Retrying (Retry(total=1, connect=None, read=None, redirect=None, status=None)) after connection broken by 'NewConnectionError('<urllib3.connection.HTTPSConnection object at 0x7fa17f2eb810>: Failed to establish a new connection: [Errno -2] Name or service not known')': /token
[2023-09-25T10:00:03.019+0000] {connectionpool.py:813} WARNING - Retrying (Retry(total=0, connect=None, read=None, redirect=None, status=None)) after connection broken by 'NewConnectionError('<urllib3.connection.HTTPSConnection object at 0x7fa17f2ebbd0>: Failed to establish a new connection: [Errno -2] Name or service not known')': /token
[2023-09-25T10:00:04.931+0000] {connectionpool.py:813} WARNING - Retrying (Retry(total=2, connect=None, read=None, redirect=None, status=None)) after connection broken by 'NewConnectionError('<urllib3.connection.HTTPSConnection object at 0x7fa17f2f6590>: Failed to establish a new connection: [Errno -2] Name or service not known')': /token
[2023-09-25T10:00:04.932+0000] {connectionpool.py:813} WARNING - Retrying (Retry(total=1, connect=None, read=None, redirect=None, status=None)) after connection broken by 'NewConnectionError('<urllib3.connection.HTTPSConnection object at 0x7fa17f2f6c90>: Failed to establish a new connection: [Errno -2] Name or service not known')': /token
[2023-09-25T10:00:04.934+0000] {connectionpool.py:813} WARNING - Retrying (Retry(total=0, connect=None, read=None, redirect=None, status=None)) after connection broken by 'NewConnectionError('<urllib3.connection.HTTPSConnection object at 0x7fa17f2fd050>: Failed to establish a new connection: [Errno -2] Name or service not known')': /token
[2023-09-25T10:00:08.841+0000] {logging_mixin.py:149} INFO - Connection Succesful
[2023-09-25T10:00:11.044+0000] {logging_mixin.py:149} INFO - Loaded 18 rows to BigQuery
[2023-09-25T10:00:11.048+0000] {python.py:183} INFO - Done. Returned value was: None
[2023-09-25T10:00:11.056+0000] {taskinstance.py:1350} INFO - Marking task as SUCCESS. dag_id=load_data, task_id=load_to_fact_table, execution_date=20230925T095500, start_date=20230925T100001, end_date=20230925T100011
[2023-09-25T10:00:11.072+0000] {local_task_job_runner.py:225} INFO - Task exited with return code 0
[2023-09-25T10:00:11.083+0000] {taskinstance.py:2651} INFO - 0 downstream tasks scheduled from follow-on schedule check
