[2023-09-23T22:01:47.279+0000] {taskinstance.py:1103} INFO - Dependencies all met for dep_context=non-requeueable deps ti=<TaskInstance: load_data.load_to_fact_table scheduled__2023-09-23T21:55:00+00:00 [queued]>
[2023-09-23T22:01:47.287+0000] {taskinstance.py:1103} INFO - Dependencies all met for dep_context=requeueable deps ti=<TaskInstance: load_data.load_to_fact_table scheduled__2023-09-23T21:55:00+00:00 [queued]>
[2023-09-23T22:01:47.287+0000] {taskinstance.py:1308} INFO - Starting attempt 1 of 1
[2023-09-23T22:01:47.299+0000] {taskinstance.py:1327} INFO - Executing <Task(_PythonDecoratedOperator): load_to_fact_table> on 2023-09-23 21:55:00+00:00
[2023-09-23T22:01:47.305+0000] {standard_task_runner.py:57} INFO - Started process 8539 to run task
[2023-09-23T22:01:47.309+0000] {standard_task_runner.py:84} INFO - Running: ['***', 'tasks', 'run', 'load_data', 'load_to_fact_table', 'scheduled__2023-09-23T21:55:00+00:00', '--job-id', '5508', '--raw', '--subdir', 'DAGS_FOLDER/load_data.py', '--cfg-path', '/tmp/tmpj7u10wtp']
[2023-09-23T22:01:47.312+0000] {standard_task_runner.py:85} INFO - Job 5508: Subtask load_to_fact_table
[2023-09-23T22:01:47.368+0000] {task_command.py:410} INFO - Running <TaskInstance: load_data.load_to_fact_table scheduled__2023-09-23T21:55:00+00:00 [running]> on host 833e75d2e24d
[2023-09-23T22:01:47.437+0000] {taskinstance.py:1547} INFO - Exporting env vars: AIRFLOW_CTX_DAG_OWNER='***' AIRFLOW_CTX_DAG_ID='load_data' AIRFLOW_CTX_TASK_ID='load_to_fact_table' AIRFLOW_CTX_EXECUTION_DATE='2023-09-23T21:55:00+00:00' AIRFLOW_CTX_TRY_NUMBER='1' AIRFLOW_CTX_DAG_RUN_ID='scheduled__2023-09-23T21:55:00+00:00'
[2023-09-23T22:01:47.515+0000] {connectionpool.py:813} WARNING - Retrying (Retry(total=2, connect=None, read=None, redirect=None, status=None)) after connection broken by 'NewConnectionError('<urllib3.connection.HTTPSConnection object at 0x7fa17f2d2bd0>: Failed to establish a new connection: [Errno -2] Name or service not known')': /token
[2023-09-23T22:01:47.517+0000] {connectionpool.py:813} WARNING - Retrying (Retry(total=1, connect=None, read=None, redirect=None, status=None)) after connection broken by 'NewConnectionError('<urllib3.connection.HTTPSConnection object at 0x7fa17f2d2f50>: Failed to establish a new connection: [Errno -2] Name or service not known')': /token
[2023-09-23T22:01:47.519+0000] {connectionpool.py:813} WARNING - Retrying (Retry(total=0, connect=None, read=None, redirect=None, status=None)) after connection broken by 'NewConnectionError('<urllib3.connection.HTTPSConnection object at 0x7fa17f2f4350>: Failed to establish a new connection: [Errno -2] Name or service not known')': /token
[2023-09-23T22:01:54.772+0000] {logging_mixin.py:149} INFO - Connection Succesful
[2023-09-23T22:01:56.668+0000] {logging_mixin.py:149} INFO - Loaded 0 rows to BigQuery
[2023-09-23T22:01:56.671+0000] {python.py:183} INFO - Done. Returned value was: None
[2023-09-23T22:01:56.683+0000] {taskinstance.py:1350} INFO - Marking task as SUCCESS. dag_id=load_data, task_id=load_to_fact_table, execution_date=20230923T215500, start_date=20230923T220147, end_date=20230923T220156
[2023-09-23T22:01:56.736+0000] {local_task_job_runner.py:225} INFO - Task exited with return code 0
[2023-09-23T22:01:56.748+0000] {taskinstance.py:2651} INFO - 0 downstream tasks scheduled from follow-on schedule check
