[2023-09-25T20:48:12.445+0000] {taskinstance.py:1103} INFO - Dependencies all met for dep_context=non-requeueable deps ti=<TaskInstance: load_data.load_to_fact_table scheduled__2023-09-25T19:05:00+00:00 [queued]>
[2023-09-25T20:48:12.451+0000] {taskinstance.py:1103} INFO - Dependencies all met for dep_context=requeueable deps ti=<TaskInstance: load_data.load_to_fact_table scheduled__2023-09-25T19:05:00+00:00 [queued]>
[2023-09-25T20:48:12.452+0000] {taskinstance.py:1308} INFO - Starting attempt 1 of 1
[2023-09-25T20:48:12.463+0000] {taskinstance.py:1327} INFO - Executing <Task(_PythonDecoratedOperator): load_to_fact_table> on 2023-09-25 19:05:00+00:00
[2023-09-25T20:48:12.468+0000] {standard_task_runner.py:57} INFO - Started process 28554 to run task
[2023-09-25T20:48:12.472+0000] {standard_task_runner.py:84} INFO - Running: ['***', 'tasks', 'run', 'load_data', 'load_to_fact_table', 'scheduled__2023-09-25T19:05:00+00:00', '--job-id', '5723', '--raw', '--subdir', 'DAGS_FOLDER/load_data.py', '--cfg-path', '/tmp/tmpd_8hdihe']
[2023-09-25T20:48:12.477+0000] {standard_task_runner.py:85} INFO - Job 5723: Subtask load_to_fact_table
[2023-09-25T20:48:12.514+0000] {task_command.py:410} INFO - Running <TaskInstance: load_data.load_to_fact_table scheduled__2023-09-25T19:05:00+00:00 [running]> on host 833e75d2e24d
[2023-09-25T20:48:12.586+0000] {taskinstance.py:1547} INFO - Exporting env vars: AIRFLOW_CTX_DAG_OWNER='***' AIRFLOW_CTX_DAG_ID='load_data' AIRFLOW_CTX_TASK_ID='load_to_fact_table' AIRFLOW_CTX_EXECUTION_DATE='2023-09-25T19:05:00+00:00' AIRFLOW_CTX_TRY_NUMBER='1' AIRFLOW_CTX_DAG_RUN_ID='scheduled__2023-09-25T19:05:00+00:00'
[2023-09-25T20:48:12.662+0000] {connectionpool.py:813} WARNING - Retrying (Retry(total=2, connect=None, read=None, redirect=None, status=None)) after connection broken by 'NewConnectionError('<urllib3.connection.HTTPSConnection object at 0x7fa17f31fdd0>: Failed to establish a new connection: [Errno -2] Name or service not known')': /token
[2023-09-25T20:48:12.664+0000] {connectionpool.py:813} WARNING - Retrying (Retry(total=1, connect=None, read=None, redirect=None, status=None)) after connection broken by 'NewConnectionError('<urllib3.connection.HTTPSConnection object at 0x7fa17f2d9850>: Failed to establish a new connection: [Errno -2] Name or service not known')': /token
[2023-09-25T20:48:12.666+0000] {connectionpool.py:813} WARNING - Retrying (Retry(total=0, connect=None, read=None, redirect=None, status=None)) after connection broken by 'NewConnectionError('<urllib3.connection.HTTPSConnection object at 0x7fa17f2d9c10>: Failed to establish a new connection: [Errno -2] Name or service not known')': /token
[2023-09-25T20:48:12.852+0000] {connectionpool.py:813} WARNING - Retrying (Retry(total=2, connect=None, read=None, redirect=None, status=None)) after connection broken by 'NewConnectionError('<urllib3.connection.HTTPSConnection object at 0x7fa17f2f15d0>: Failed to establish a new connection: [Errno -2] Name or service not known')': /token
[2023-09-25T20:48:12.854+0000] {connectionpool.py:813} WARNING - Retrying (Retry(total=1, connect=None, read=None, redirect=None, status=None)) after connection broken by 'NewConnectionError('<urllib3.connection.HTTPSConnection object at 0x7fa17f2f1bd0>: Failed to establish a new connection: [Errno -2] Name or service not known')': /token
[2023-09-25T20:48:12.856+0000] {connectionpool.py:813} WARNING - Retrying (Retry(total=0, connect=None, read=None, redirect=None, status=None)) after connection broken by 'NewConnectionError('<urllib3.connection.HTTPSConnection object at 0x7fa17f2f1f90>: Failed to establish a new connection: [Errno -2] Name or service not known')': /token
[2023-09-25T20:48:23.283+0000] {logging_mixin.py:149} INFO - Connection Succesful
[2023-09-25T20:48:25.112+0000] {logging_mixin.py:149} INFO - Loaded 0 rows to BigQuery
[2023-09-25T20:48:25.115+0000] {python.py:183} INFO - Done. Returned value was: None
[2023-09-25T20:48:25.124+0000] {taskinstance.py:1350} INFO - Marking task as SUCCESS. dag_id=load_data, task_id=load_to_fact_table, execution_date=20230925T190500, start_date=20230925T204812, end_date=20230925T204825
[2023-09-25T20:48:25.171+0000] {local_task_job_runner.py:225} INFO - Task exited with return code 0
[2023-09-25T20:48:25.183+0000] {taskinstance.py:2651} INFO - 0 downstream tasks scheduled from follow-on schedule check
