[2023-09-24T13:42:08.676+0000] {taskinstance.py:1103} INFO - Dependencies all met for dep_context=non-requeueable deps ti=<TaskInstance: load_data.load_to_fact_table scheduled__2023-09-24T00:15:00+00:00 [queued]>
[2023-09-24T13:42:08.685+0000] {taskinstance.py:1103} INFO - Dependencies all met for dep_context=requeueable deps ti=<TaskInstance: load_data.load_to_fact_table scheduled__2023-09-24T00:15:00+00:00 [queued]>
[2023-09-24T13:42:08.685+0000] {taskinstance.py:1308} INFO - Starting attempt 1 of 1
[2023-09-24T13:42:08.697+0000] {taskinstance.py:1327} INFO - Executing <Task(_PythonDecoratedOperator): load_to_fact_table> on 2023-09-24 00:15:00+00:00
[2023-09-24T13:42:08.703+0000] {standard_task_runner.py:57} INFO - Started process 11248 to run task
[2023-09-24T13:42:08.709+0000] {standard_task_runner.py:84} INFO - Running: ['***', 'tasks', 'run', 'load_data', 'load_to_fact_table', 'scheduled__2023-09-24T00:15:00+00:00', '--job-id', '5536', '--raw', '--subdir', 'DAGS_FOLDER/load_data.py', '--cfg-path', '/tmp/tmp8m8ilbcz']
[2023-09-24T13:42:08.716+0000] {standard_task_runner.py:85} INFO - Job 5536: Subtask load_to_fact_table
[2023-09-24T13:42:08.769+0000] {task_command.py:410} INFO - Running <TaskInstance: load_data.load_to_fact_table scheduled__2023-09-24T00:15:00+00:00 [running]> on host 833e75d2e24d
[2023-09-24T13:42:08.851+0000] {taskinstance.py:1547} INFO - Exporting env vars: AIRFLOW_CTX_DAG_OWNER='***' AIRFLOW_CTX_DAG_ID='load_data' AIRFLOW_CTX_TASK_ID='load_to_fact_table' AIRFLOW_CTX_EXECUTION_DATE='2023-09-24T00:15:00+00:00' AIRFLOW_CTX_TRY_NUMBER='1' AIRFLOW_CTX_DAG_RUN_ID='scheduled__2023-09-24T00:15:00+00:00'
[2023-09-24T13:42:08.943+0000] {connectionpool.py:813} WARNING - Retrying (Retry(total=2, connect=None, read=None, redirect=None, status=None)) after connection broken by 'NewConnectionError('<urllib3.connection.HTTPSConnection object at 0x7fa17f31fdd0>: Failed to establish a new connection: [Errno -2] Name or service not known')': /token
[2023-09-24T13:42:08.946+0000] {connectionpool.py:813} WARNING - Retrying (Retry(total=1, connect=None, read=None, redirect=None, status=None)) after connection broken by 'NewConnectionError('<urllib3.connection.HTTPSConnection object at 0x7fa17f2d9850>: Failed to establish a new connection: [Errno -2] Name or service not known')': /token
[2023-09-24T13:42:08.949+0000] {connectionpool.py:813} WARNING - Retrying (Retry(total=0, connect=None, read=None, redirect=None, status=None)) after connection broken by 'NewConnectionError('<urllib3.connection.HTTPSConnection object at 0x7fa17f2d9c10>: Failed to establish a new connection: [Errno -2] Name or service not known')': /token
[2023-09-24T13:42:08.975+0000] {connectionpool.py:813} WARNING - Retrying (Retry(total=2, connect=None, read=None, redirect=None, status=None)) after connection broken by 'NewConnectionError('<urllib3.connection.HTTPSConnection object at 0x7fa17f2f15d0>: Failed to establish a new connection: [Errno -2] Name or service not known')': /token
[2023-09-24T13:42:08.978+0000] {connectionpool.py:813} WARNING - Retrying (Retry(total=1, connect=None, read=None, redirect=None, status=None)) after connection broken by 'NewConnectionError('<urllib3.connection.HTTPSConnection object at 0x7fa17f2f1bd0>: Failed to establish a new connection: [Errno -2] Name or service not known')': /token
[2023-09-24T13:42:08.981+0000] {connectionpool.py:813} WARNING - Retrying (Retry(total=0, connect=None, read=None, redirect=None, status=None)) after connection broken by 'NewConnectionError('<urllib3.connection.HTTPSConnection object at 0x7fa17f2f1f90>: Failed to establish a new connection: [Errno -2] Name or service not known')': /token
[2023-09-24T13:42:10.438+0000] {connectionpool.py:813} WARNING - Retrying (Retry(total=2, connect=None, read=None, redirect=None, status=None)) after connection broken by 'NewConnectionError('<urllib3.connection.HTTPSConnection object at 0x7fa17f2fb950>: Failed to establish a new connection: [Errno -2] Name or service not known')': /token
[2023-09-24T13:42:10.441+0000] {connectionpool.py:813} WARNING - Retrying (Retry(total=1, connect=None, read=None, redirect=None, status=None)) after connection broken by 'NewConnectionError('<urllib3.connection.HTTPSConnection object at 0x7fa17f2fbfd0>: Failed to establish a new connection: [Errno -2] Name or service not known')': /token
[2023-09-24T13:42:10.443+0000] {connectionpool.py:813} WARNING - Retrying (Retry(total=0, connect=None, read=None, redirect=None, status=None)) after connection broken by 'NewConnectionError('<urllib3.connection.HTTPSConnection object at 0x7fa17f305410>: Failed to establish a new connection: [Errno -2] Name or service not known')': /token
[2023-09-24T13:42:11.946+0000] {connectionpool.py:813} WARNING - Retrying (Retry(total=2, connect=None, read=None, redirect=None, status=None)) after connection broken by 'NewConnectionError('<urllib3.connection.HTTPSConnection object at 0x7fa17f2d9490>: Failed to establish a new connection: [Errno -2] Name or service not known')': /token
[2023-09-24T13:42:11.948+0000] {connectionpool.py:813} WARNING - Retrying (Retry(total=1, connect=None, read=None, redirect=None, status=None)) after connection broken by 'NewConnectionError('<urllib3.connection.HTTPSConnection object at 0x7fa17f2d9d90>: Failed to establish a new connection: [Errno -2] Name or service not known')': /token
[2023-09-24T13:42:11.950+0000] {connectionpool.py:813} WARNING - Retrying (Retry(total=0, connect=None, read=None, redirect=None, status=None)) after connection broken by 'NewConnectionError('<urllib3.connection.HTTPSConnection object at 0x7fa17f2d9890>: Failed to establish a new connection: [Errno -2] Name or service not known')': /token
[2023-09-24T13:42:28.031+0000] {logging_mixin.py:149} INFO - Connection Succesful
[2023-09-24T13:42:30.199+0000] {logging_mixin.py:149} INFO - Loaded 0 rows to BigQuery
[2023-09-24T13:42:30.203+0000] {python.py:183} INFO - Done. Returned value was: None
[2023-09-24T13:42:30.226+0000] {taskinstance.py:1350} INFO - Marking task as SUCCESS. dag_id=load_data, task_id=load_to_fact_table, execution_date=20230924T001500, start_date=20230924T134208, end_date=20230924T134230
[2023-09-24T13:42:30.279+0000] {local_task_job_runner.py:225} INFO - Task exited with return code 0
[2023-09-24T13:42:30.295+0000] {taskinstance.py:2651} INFO - 0 downstream tasks scheduled from follow-on schedule check
