[2023-09-24T17:02:45.105+0000] {taskinstance.py:1103} INFO - Dependencies all met for dep_context=non-requeueable deps ti=<TaskInstance: load_data.load_to_fact_table scheduled__2023-09-24T16:10:00+00:00 [queued]>
[2023-09-24T17:02:45.112+0000] {taskinstance.py:1103} INFO - Dependencies all met for dep_context=requeueable deps ti=<TaskInstance: load_data.load_to_fact_table scheduled__2023-09-24T16:10:00+00:00 [queued]>
[2023-09-24T17:02:45.112+0000] {taskinstance.py:1308} INFO - Starting attempt 1 of 1
[2023-09-24T17:02:45.126+0000] {taskinstance.py:1327} INFO - Executing <Task(_PythonDecoratedOperator): load_to_fact_table> on 2023-09-24 16:10:00+00:00
[2023-09-24T17:02:45.130+0000] {standard_task_runner.py:57} INFO - Started process 14038 to run task
[2023-09-24T17:02:45.134+0000] {standard_task_runner.py:84} INFO - Running: ['***', 'tasks', 'run', 'load_data', 'load_to_fact_table', 'scheduled__2023-09-24T16:10:00+00:00', '--job-id', '5567', '--raw', '--subdir', 'DAGS_FOLDER/load_data.py', '--cfg-path', '/tmp/tmpityps7ia']
[2023-09-24T17:02:45.138+0000] {standard_task_runner.py:85} INFO - Job 5567: Subtask load_to_fact_table
[2023-09-24T17:02:45.212+0000] {task_command.py:410} INFO - Running <TaskInstance: load_data.load_to_fact_table scheduled__2023-09-24T16:10:00+00:00 [running]> on host 833e75d2e24d
[2023-09-24T17:02:45.323+0000] {taskinstance.py:1547} INFO - Exporting env vars: AIRFLOW_CTX_DAG_OWNER='***' AIRFLOW_CTX_DAG_ID='load_data' AIRFLOW_CTX_TASK_ID='load_to_fact_table' AIRFLOW_CTX_EXECUTION_DATE='2023-09-24T16:10:00+00:00' AIRFLOW_CTX_TRY_NUMBER='1' AIRFLOW_CTX_DAG_RUN_ID='scheduled__2023-09-24T16:10:00+00:00'
[2023-09-24T17:02:45.403+0000] {connectionpool.py:813} WARNING - Retrying (Retry(total=2, connect=None, read=None, redirect=None, status=None)) after connection broken by 'NewConnectionError('<urllib3.connection.HTTPSConnection object at 0x7fa17f31fdd0>: Failed to establish a new connection: [Errno -2] Name or service not known')': /token
[2023-09-24T17:02:45.406+0000] {connectionpool.py:813} WARNING - Retrying (Retry(total=1, connect=None, read=None, redirect=None, status=None)) after connection broken by 'NewConnectionError('<urllib3.connection.HTTPSConnection object at 0x7fa17f2d9850>: Failed to establish a new connection: [Errno -2] Name or service not known')': /token
[2023-09-24T17:02:45.408+0000] {connectionpool.py:813} WARNING - Retrying (Retry(total=0, connect=None, read=None, redirect=None, status=None)) after connection broken by 'NewConnectionError('<urllib3.connection.HTTPSConnection object at 0x7fa17f2d9c10>: Failed to establish a new connection: [Errno -2] Name or service not known')': /token
[2023-09-24T17:02:55.699+0000] {logging_mixin.py:149} INFO - Connection Succesful
[2023-09-24T17:02:57.565+0000] {logging_mixin.py:149} INFO - Loaded 19 rows to BigQuery
[2023-09-24T17:02:57.569+0000] {python.py:183} INFO - Done. Returned value was: None
[2023-09-24T17:02:57.577+0000] {taskinstance.py:1350} INFO - Marking task as SUCCESS. dag_id=load_data, task_id=load_to_fact_table, execution_date=20230924T161000, start_date=20230924T170245, end_date=20230924T170257
[2023-09-24T17:02:57.632+0000] {local_task_job_runner.py:225} INFO - Task exited with return code 0
[2023-09-24T17:02:57.643+0000] {taskinstance.py:2651} INFO - 0 downstream tasks scheduled from follow-on schedule check
