[2023-09-24T13:42:09.283+0000] {taskinstance.py:1103} INFO - Dependencies all met for dep_context=non-requeueable deps ti=<TaskInstance: load_data.load_to_fact_table scheduled__2023-09-24T13:35:00+00:00 [queued]>
[2023-09-24T13:42:09.291+0000] {taskinstance.py:1103} INFO - Dependencies all met for dep_context=requeueable deps ti=<TaskInstance: load_data.load_to_fact_table scheduled__2023-09-24T13:35:00+00:00 [queued]>
[2023-09-24T13:42:09.291+0000] {taskinstance.py:1308} INFO - Starting attempt 1 of 1
[2023-09-24T13:42:09.304+0000] {taskinstance.py:1327} INFO - Executing <Task(_PythonDecoratedOperator): load_to_fact_table> on 2023-09-24 13:35:00+00:00
[2023-09-24T13:42:09.310+0000] {standard_task_runner.py:57} INFO - Started process 11249 to run task
[2023-09-24T13:42:09.314+0000] {standard_task_runner.py:84} INFO - Running: ['***', 'tasks', 'run', 'load_data', 'load_to_fact_table', 'scheduled__2023-09-24T13:35:00+00:00', '--job-id', '5537', '--raw', '--subdir', 'DAGS_FOLDER/load_data.py', '--cfg-path', '/tmp/tmptig5f144']
[2023-09-24T13:42:09.318+0000] {standard_task_runner.py:85} INFO - Job 5537: Subtask load_to_fact_table
[2023-09-24T13:42:09.364+0000] {task_command.py:410} INFO - Running <TaskInstance: load_data.load_to_fact_table scheduled__2023-09-24T13:35:00+00:00 [running]> on host 833e75d2e24d
[2023-09-24T13:42:09.473+0000] {taskinstance.py:1547} INFO - Exporting env vars: AIRFLOW_CTX_DAG_OWNER='***' AIRFLOW_CTX_DAG_ID='load_data' AIRFLOW_CTX_TASK_ID='load_to_fact_table' AIRFLOW_CTX_EXECUTION_DATE='2023-09-24T13:35:00+00:00' AIRFLOW_CTX_TRY_NUMBER='1' AIRFLOW_CTX_DAG_RUN_ID='scheduled__2023-09-24T13:35:00+00:00'
[2023-09-24T13:42:09.560+0000] {connectionpool.py:813} WARNING - Retrying (Retry(total=2, connect=None, read=None, redirect=None, status=None)) after connection broken by 'NewConnectionError('<urllib3.connection.HTTPSConnection object at 0x7fa17f2d2bd0>: Failed to establish a new connection: [Errno -2] Name or service not known')': /token
[2023-09-24T13:42:09.563+0000] {connectionpool.py:813} WARNING - Retrying (Retry(total=1, connect=None, read=None, redirect=None, status=None)) after connection broken by 'NewConnectionError('<urllib3.connection.HTTPSConnection object at 0x7fa17f2d2f50>: Failed to establish a new connection: [Errno -2] Name or service not known')': /token
[2023-09-24T13:42:09.565+0000] {connectionpool.py:813} WARNING - Retrying (Retry(total=0, connect=None, read=None, redirect=None, status=None)) after connection broken by 'NewConnectionError('<urllib3.connection.HTTPSConnection object at 0x7fa17f2f4350>: Failed to establish a new connection: [Errno -2] Name or service not known')': /token
[2023-09-24T13:42:10.430+0000] {connectionpool.py:813} WARNING - Retrying (Retry(total=2, connect=None, read=None, redirect=None, status=None)) after connection broken by 'NewConnectionError('<urllib3.connection.HTTPSConnection object at 0x7fa17f2f4cd0>: Failed to establish a new connection: [Errno -2] Name or service not known')': /token
[2023-09-24T13:42:10.433+0000] {connectionpool.py:813} WARNING - Retrying (Retry(total=1, connect=None, read=None, redirect=None, status=None)) after connection broken by 'NewConnectionError('<urllib3.connection.HTTPSConnection object at 0x7fa17f2fb310>: Failed to establish a new connection: [Errno -2] Name or service not known')': /token
[2023-09-24T13:42:10.436+0000] {connectionpool.py:813} WARNING - Retrying (Retry(total=0, connect=None, read=None, redirect=None, status=None)) after connection broken by 'NewConnectionError('<urllib3.connection.HTTPSConnection object at 0x7fa17f2fb6d0>: Failed to establish a new connection: [Errno -2] Name or service not known')': /token
[2023-09-24T13:42:11.482+0000] {connectionpool.py:813} WARNING - Retrying (Retry(total=2, connect=None, read=None, redirect=None, status=None)) after connection broken by 'NewConnectionError('<urllib3.connection.HTTPSConnection object at 0x7fa17f305090>: Failed to establish a new connection: [Errno -2] Name or service not known')': /token
[2023-09-24T13:42:11.485+0000] {connectionpool.py:813} WARNING - Retrying (Retry(total=1, connect=None, read=None, redirect=None, status=None)) after connection broken by 'NewConnectionError('<urllib3.connection.HTTPSConnection object at 0x7fa17f305790>: Failed to establish a new connection: [Errno -2] Name or service not known')': /token
[2023-09-24T13:42:11.489+0000] {connectionpool.py:813} WARNING - Retrying (Retry(total=0, connect=None, read=None, redirect=None, status=None)) after connection broken by 'NewConnectionError('<urllib3.connection.HTTPSConnection object at 0x7fa17f305b10>: Failed to establish a new connection: [Errno -2] Name or service not known')': /token
[2023-09-24T13:42:12.439+0000] {connectionpool.py:813} WARNING - Retrying (Retry(total=2, connect=None, read=None, redirect=None, status=None)) after connection broken by 'NewConnectionError('<urllib3.connection.HTTPSConnection object at 0x7fa17f2f40d0>: Failed to establish a new connection: [Errno -2] Name or service not known')': /token
[2023-09-24T13:42:12.441+0000] {connectionpool.py:813} WARNING - Retrying (Retry(total=1, connect=None, read=None, redirect=None, status=None)) after connection broken by 'NewConnectionError('<urllib3.connection.HTTPSConnection object at 0x7fa17f2d2f50>: Failed to establish a new connection: [Errno -2] Name or service not known')': /token
[2023-09-24T13:42:12.443+0000] {connectionpool.py:813} WARNING - Retrying (Retry(total=0, connect=None, read=None, redirect=None, status=None)) after connection broken by 'NewConnectionError('<urllib3.connection.HTTPSConnection object at 0x7fa17f2d2950>: Failed to establish a new connection: [Errno -2] Name or service not known')': /token
[2023-09-24T13:42:28.011+0000] {logging_mixin.py:149} INFO - Connection Succesful
[2023-09-24T13:42:29.821+0000] {logging_mixin.py:149} INFO - Loaded 0 rows to BigQuery
[2023-09-24T13:42:29.824+0000] {python.py:183} INFO - Done. Returned value was: None
[2023-09-24T13:42:29.832+0000] {taskinstance.py:1350} INFO - Marking task as SUCCESS. dag_id=load_data, task_id=load_to_fact_table, execution_date=20230924T133500, start_date=20230924T134209, end_date=20230924T134229
[2023-09-24T13:42:29.846+0000] {local_task_job_runner.py:225} INFO - Task exited with return code 0
[2023-09-24T13:42:29.858+0000] {taskinstance.py:2651} INFO - 0 downstream tasks scheduled from follow-on schedule check
